<?xml version="1.0"?>
<robot name="arm_6dof" xmlns:xacro="http://www.ros.org/wiki/xacro">

  <link name="world"/>
  <joint name="fixed" type="fixed">
    <parent link="world"/>
    <child link="base_link"/>
  </joint>

  <link name="base_link">
    <visual><geometry><cylinder length="0.1" radius="0.2"/></geometry></visual>
    <collision><geometry><cylinder length="0.1" radius="0.2"/></geometry></collision>
    <inertial><mass value="2.0"/><inertia ixx="0.1" ixy="0" ixz="0" iyy="0.1" iyz="0" izz="0.1"/></inertial>
  </link>

  <joint name="joint1" type="revolute">
    <parent link="base_link"/><child link="link1"/>
    <axis xyz="0 0 1"/><origin xyz="0 0 0.1"/>
    <limit lower="-3.14" upper="3.14" effort="10" velocity="1.0"/>
  </joint>
  <link name="link1">
    <visual><geometry><cylinder length="0.2" radius="0.1"/></geometry><origin xyz="0 0 0.1"/></visual>
    <inertial><mass value="1.0"/><inertia ixx="0.01" iyy="0.01" izz="0.01" ixy="0" ixz="0" iyz="0"/></inertial>
  </link>

  <joint name="joint2" type="revolute">
    <parent link="link1"/><child link="link2"/>
    <axis xyz="0 1 0"/><origin xyz="0 0 0.2"/>
    <limit lower="-1.57" upper="1.57" effort="10" velocity="1.0"/>
  </joint>
  <link name="link2">
    <visual><geometry><box size="0.1 0.1 0.4"/></geometry><origin xyz="0 0 0.2"/></visual>
    <inertial><mass value="1.0"/><inertia ixx="0.01" iyy="0.01" izz="0.01" ixy="0" ixz="0" iyz="0"/></inertial>
  </link>

  <joint name="joint3" type="revolute">
    <parent link="link2"/><child link="link3"/>
    <axis xyz="0 1 0"/><origin xyz="0 0 0.4"/>
    <limit lower="-1.57" upper="1.57" effort="10" velocity="1.0"/>
  </joint>
  <link name="link3">
    <visual><geometry><box size="0.1 0.1 0.4"/></geometry><origin xyz="0 0 0.2"/></visual>
    <inertial><mass value="1.0"/><inertia ixx="0.01" iyy="0.01" izz="0.01" ixy="0" ixz="0" iyz="0"/></inertial>
  </link>

  <joint name="joint4" type="revolute">
    <parent link="link3"/><child link="link4"/>
    <axis xyz="0 0 1"/><origin xyz="0 0 0.4"/>
    <limit lower="-3.14" upper="3.14" effort="10" velocity="1.0"/>
  </joint>
  <link name="link4">
    <visual><geometry><cylinder length="0.1" radius="0.05"/></geometry><origin xyz="0 0 0.05"/></visual>
    <inertial><mass value="0.5"/><inertia ixx="0.01" iyy="0.01" izz="0.01" ixy="0" ixz="0" iyz="0"/></inertial>
  </link>

  <joint name="joint5" type="revolute">
    <parent link="link4"/><child link="link5"/>
    <axis xyz="0 1 0"/><origin xyz="0 0 0.1"/>
    <limit lower="-1.57" upper="1.57" effort="10" velocity="1.0"/>
  </joint>
  <link name="link5">
    <visual><geometry><cylinder length="0.1" radius="0.05"/></geometry><origin xyz="0 0 0.05"/></visual>
    <inertial><mass value="0.5"/><inertia ixx="0.01" iyy="0.01" izz="0.01" ixy="0" ixz="0" iyz="0"/></inertial>
  </link>

  <joint name="joint6" type="revolute">
    <parent link="link5"/><child link="link6"/>
    <axis xyz="1 0 0"/><origin xyz="0 0 0.1"/>
    <limit lower="-3.14" upper="3.14" effort="10" velocity="1.0"/>
  </joint>
  <link name="link6">
    <visual><geometry><box size="0.1 0.02 0.02"/></geometry><origin xyz="0.05 0 0"/></visual>
    <inertial><mass value="0.2"/><inertia ixx="0.001" iyy="0.001" izz="0.001" ixy="0" ixz="0" iyz="0"/></inertial>
  </link>

  <ros2_control name="GazeboSimSystem" type="system">
    <hardware><plugin>gz_ros2_control/GazeboSimSystem</plugin></hardware>
    <joint name="joint1"><command_interface name="position"/><state_interface name="position"/><state_interface name="velocity"/></joint>
    <joint name="joint2"><command_interface name="position"/><state_interface name="position"/><state_interface name="velocity"/></joint>
    <joint name="joint3"><command_interface name="position"/><state_interface name="position"/><state_interface name="velocity"/></joint>
    <joint name="joint4"><command_interface name="position"/><state_interface name="position"/><state_interface name="velocity"/></joint>
    <joint name="joint5"><command_interface name="position"/><state_interface name="position"/><state_interface name="velocity"/></joint>
    <joint name="joint6"><command_interface name="position"/><state_interface name="position"/><state_interface name="velocity"/></joint>
  </ros2_control>

  <gazebo>
    <plugin filename="gz_ros2_control-system" name="gz_ros2_control::GazeboSimControl">
      <parameters>$(find my_arm_sim)/config/controllers.yaml</parameters>
    </plugin>
  </gazebo>

</robot>
